Workbook

Sheet Trade Log
A1: VALORANT PAPER TRADE LOG
A3: Trade # | B3: Date | C3: Match | D3: Map | E3: Model Prob | F3: Market Price | G3: Edge | H3: Entry Price | I3: Highest Price | J3: Lowest Price | K3: Exit Price | L3: Exit Round | M3: Exit Reason | N3: P/L (cents) | O3: P/L (%) | P3: Running P/L
A4: 1 | B4: 3/6/2026 | C4: Furia vs PRX | D4: Haven | E4: 0.392 | F4: 0.3 | G4: =IF(E4="","",E4-F4) -> 0.092 | H4: 0.3 | K4: 0.21 | L4: 5 | M4: Catastrophic Stop | N4: =IF(OR(K4="",H4=""),"",K4-H4) -> -0.09 | O4: =IF(OR(K4="",H4=""),"",(K4-H4)/H4) -> -0.3 | P4: =IF(N4="","",SUM(N$4:N4)) -> -0.09
A5: 2 | B5: 3/6/2026 | C5: Furia vs PRX | D5: Breeze | E5: 0.612 | F5: 0.6 | G5: =IF(E5="","",E5-F5) -> 0.012 | H5: 0.6 | K5: 1 | L5: 17 | M5: Time Exit | N5: =IF(OR(K5="",H5=""),"",K5-H5) -> 0.4 | O5: =IF(OR(K5="",H5=""),"",(K5-H5)/H5) -> 0.66666667 | P5: =IF(N5="","",SUM(N$4:N5)) -> 0.31
A6: 3 | B6: 3/6/2026 | C6: Furia vs PRX | D6: Split | E6: 0.404 | F6: 0.35 | G6: =IF(E6="","",E6-F6) -> 0.054 | H6: 0.35 | K6: 0.648 | L6: 10 | M6: Trailing Stop | N6: =IF(OR(K6="",H6=""),"",K6-H6) -> 0.298 | O6: =IF(OR(K6="",H6=""),"",(K6-H6)/H6) -> 0.85142857 | P6: =IF(N6="","",SUM(N$4:N6)) -> 0.608
A7: 4 | G7: =IF(E7="","",E7-F7) | N7: =IF(OR(K7="",H7=""),"",K7-H7) | O7: =IF(OR(K7="",H7=""),"",(K7-H7)/H7) | P7: =IF(N7="","",SUM(N$4:N7))
A8: 5 | G8: =IF(E8="","",E8-F8) | N8: =IF(OR(K8="",H8=""),"",K8-H8) | O8: =IF(OR(K8="",H8=""),"",(K8-H8)/H8) | P8: =IF(N8="","",SUM(N$4:N8))
A9: 6 | G9: =IF(E9="","",E9-F9) | N9: =IF(OR(K9="",H9=""),"",K9-H9) | O9: =IF(OR(K9="",H9=""),"",(K9-H9)/H9) | P9: =IF(N9="","",SUM(N$4:N9))
A10: 7 | G10: =IF(E10="","",E10-F10) | N10: =IF(OR(K10="",H10=""),"",K10-H10) | O10: =IF(OR(K10="",H10=""),"",(K10-H10)/H10) | P10: =IF(N10="","",SUM(N$4:N10))
A11: 8 | G11: =IF(E11="","",E11-F11) | N11: =IF(OR(K11="",H11=""),"",K11-H11) | O11: =IF(OR(K11="",H11=""),"",(K11-H11)/H11) | P11: =IF(N11="","",SUM(N$4:N11))
A12: 9 | G12: =IF(E12="","",E12-F12) | N12: =IF(OR(K12="",H12=""),"",K12-H12) | O12: =IF(OR(K12="",H12=""),"",(K12-H12)/H12) | P12: =IF(N12="","",SUM(N$4:N12))
A13: 10 | G13: =IF(E13="","",E13-F13) | N13: =IF(OR(K13="",H13=""),"",K13-H13) | O13: =IF(OR(K13="",H13=""),"",(K13-H13)/H13) | P13: =IF(N13="","",SUM(N$4:N13))
A14: 11 | G14: =IF(E14="","",E14-F14) | N14: =IF(OR(K14="",H14=""),"",K14-H14) | O14: =IF(OR(K14="",H14=""),"",(K14-H14)/H14) | P14: =IF(N14="","",SUM(N$4:N14))
A15: 12 | G15: =IF(E15="","",E15-F15) | N15: =IF(OR(K15="",H15=""),"",K15-H15) | O15: =IF(OR(K15="",H15=""),"",(K15-H15)/H15) | P15: =IF(N15="","",SUM(N$4:N15))
A16: 13 | G16: =IF(E16="","",E16-F16) | N16: =IF(OR(K16="",H16=""),"",K16-H16) | O16: =IF(OR(K16="",H16=""),"",(K16-H16)/H16) | P16: =IF(N16="","",SUM(N$4:N16))
A17: 14 | G17: =IF(E17="","",E17-F17) | N17: =IF(OR(K17="",H17=""),"",K17-H17) | O17: =IF(OR(K17="",H17=""),"",(K17-H17)/H17) | P17: =IF(N17="","",SUM(N$4:N17))
A18: 15 | G18: =IF(E18="","",E18-F18) | N18: =IF(OR(K18="",H18=""),"",K18-H18) | O18: =IF(OR(K18="",H18=""),"",(K18-H18)/H18) | P18: =IF(N18="","",SUM(N$4:N18))
... A53: 50 | G53: =IF(E53="","",E53-F53) | N53: =IF(OR(K53="",H53=""),"",K53-H53) | O53: =IF(OR(K53="",H53=""),"",(K53-H53)/H53) | P53: =IF(N53="","",SUM(N$4:N53))

Sheet Dashboard
A1: PERFORMANCE DASHBOARD
A3: Metric | B3: Value | D3: Exit Reason | E3: Count | F3: Avg P/L
A4: Total Trades | B4: =COUNTA('Trade Log'!H4:H53) -> 3 | D4: Trailing Stop | E4: =COUNTIF('Trade Log'!M4:M53,D4) -> 1 | F4: =IF(E4=0,"",AVERAGEIF('Trade Log'!M4:M53,D4,'Trade Log'!N4:N53)) -> 0.298
A5: Winning Trades | B5: =COUNTIF('Trade Log'!N4:N53,">"&0) -> 2 | D5: Time Exit | E5: =COUNTIF('Trade Log'!M4:M53,D5) -> 1 | F5: =IF(E5=0,"",AVERAGEIF('Trade Log'!M4:M53,D5,'Trade Log'!N4:N53)) -> 0.4
A6: Losing Trades | B6: =COUNTIF('Trade Log'!N4:N53,"<"&0) -> 1 | D6: Catastrophic Stop | E6: =COUNTIF('Trade Log'!M4:M53,D6) -> 1 | F6: =IF(E6=0,"",AVERAGEIF('Trade Log'!M4:M53,D6,'Trade Log'!N4:N53)) -> -0.09
A7: Win Rate | B7: =IF(B4=0,"",B5/B4) -> 0.66666667 | D7: Breakeven Exit | E7: =COUNTIF('Trade Log'!M4:M53,D7) -> 0 | F7: =IF(E7=0,"",AVERAGEIF('Trade Log'!M4:M53,D7,'Trade Log'!N4:N53))
A9: Total P/L (cents) | B9: =SUM('Trade Log'!N4:N53) -> 0.608
A10: Avg Win (cents) | B10: =IF(B5=0,"",AVERAGEIF('Trade Log'!N4:N53,">"&0)) -> 0.349
A11: Avg Loss (cents) | B11: =IF(B6=0,"",AVERAGEIF('Trade Log'!N4:N53,"<"&0)) -> -0.09
A12: Largest Win | B12: =IF(B4=0,"",MAX('Trade Log'!N4:N53)) -> 0.4
A13: Largest Loss | B13: =IF(B4=0,"",MIN('Trade Log'!N4:N53)) -> -0.09
A15: Avg Edge at Entry | B15: =IF(B4=0,"",AVERAGE('Trade Log'!G4:G53)) -> 0.052666667
A16: Avg P/L % | B16: =IF(B4=0,"",AVERAGE('Trade Log'!O4:O53)) -> 0.40603175

Sheet Threshold Calculator
A1: LIVE THRESHOLD CALCULATOR
A3: ENTRY PRICE (cents): | C3: 35
A4: CURRENT PEAK (cents): | C4: 72
A6: PHASE 1 — ROUNDS 1-4 (Upside Only)
A7: Condition | B7: Threshold Price | C7: Floor Moves To | D7: Floor Value | E7: Sell?
A8: Catastrophic Stop (-30%) | B8: =$C$3*0.7 -> 24.5 | C8: Emergency exit | D8: =$C$3*0.7 -> 24.5 | E8: YES - sell immediately
A9: Price drops (above -30%) | B9: N/A | C9: No change | D9: N/A | E9: NO - Phase 1 holds
A10: Price hits +10% | B10: =$C$3*1.1 -> 38.5 | C10: Entry (breakeven) | D10: =$C$3 -> 35 | E10: NO - floor moves up only
A11: Price hits +20% | B11: =$C$3*1.2 -> 42 | C11: +10% above entry | D11: =$C$3*1.1 -> 38.5 | E11: NO - floor moves up only
A13: PHASE 2 — ROUND 5+ (Active Management)
A14: Position At | B14: Threshold Price | C14: Floor Description | D14: Floor Value | E14: Sell Trigger
A15: Below +10% | B15: =IF($C$3*1.1>0,$C$3*1.1,"") -> 38.5 | C15: Entry - 15% | D15: =$C$3*0.85 -> 29.75 | E15: =IF($C$3*0.85>0,"Price drops to "&TEXT($C$3*0.85,"0.00")&"c","") -> Price drops to 29.75c
A16: +10% above entry | B16: =$C$3*1.1 -> 38.5 | C16: Entry (breakeven) | D16: =$C$3 -> 35 | E16: =IF($C$3>0,"Price drops to "&TEXT($C$3,"0.00")&"c","") -> Price drops to 35.00c
A17: +20% above entry | B17: =$C$3*1.2 -> 42 | C17: +10% above entry | D17: =$C$3*1.1 -> 38.5 | E17: =IF($C$3*1.1>0,"Price drops to "&TEXT($C$3*1.1,"0.00")&"c","") -> Price drops to 38.50c
A18: +30% above entry | B18: =$C$3*1.3 -> 45.5 | C18: Peak × 0.9 | D18: =$C$4*0.9 -> 64.8 | E18: =IF($C$4*0.9>0,"Price drops to "&TEXT($C$4*0.9,"0.00")&"c","") -> Price drops to 64.80c
A19: +40% above entry | B19: =$C$3*1.4 -> 49 | C19: Peak × 0.9 | D19: =$C$4*0.9 -> 64.8 | E19: =IF($C$4*0.9>0,"Price drops to "&TEXT($C$4*0.9,"0.00")&"c","") -> Price drops to 64.80c
A20: +50% above entry | B20: =$C$3*1.5 -> 52.5 | C20: Peak × 0.9 | D20: =$C$4*0.9 -> 64.8 | E20: =IF($C$4*0.9>0,"Price drops to "&TEXT($C$4*0.9,"0.00")&"c","") -> Price drops to 64.80c
A22: QUICK REFERENCE — Key Prices for This Trade
A23: Price Level | B23: Value (cents)
A24: Catastrophic Stop (sell immediately) | B24: =$C$3*0.7 -> 24.5
A25: Phase 2 Stop-Loss | B25: =$C$3*0.85 -> 29.75
A26: Breakeven Floor | B26: =$C$3 -> 35
A27: +10% Threshold | B27: =$C$3*1.1 -> 38.5
A28: +20% Threshold | B28: =$C$3*1.2 -> 42
A29: Current Trailing Floor (if past +20%) | B29: =$C$4*0.9 -> 64.8

Sheet Cashflow
A1: CASHFLOW TRACKER
A3: Starting Balance ($): | B3: 1000
A4: Bet Size ($): | B4: 100
A6: Trade # | B6: P/L (%) | C6: P/L ($) | D6: Balance
A7: =IF('Trade Log'!O4="","",1) -> 1 | B7: =IF('Trade Log'!O4="","",'Trade Log'!O4) -> -0.3 | C7: =IF(B7="","",$B$4*B7) -> -30 | D7: =IF(C7="",$B$3,$B$3+C7) -> 970
A8: =IF('Trade Log'!O5="","",2) -> 2 | B8: =IF('Trade Log'!O5="","",'Trade Log'!O5) -> 0.66666667 | C8: =IF(B8="","",$B$4*B8) -> 66.666667 | D8: =IF(C8="",IF(D7="",$B$3,D7),D7+C8) -> 1036.6667
A9: =IF('Trade Log'!O6="","",3) -> 3 | B9: =IF('Trade Log'!O6="","",'Trade Log'!O6) -> 0.85142857 | C9: =IF(B9="","",$B$4*B9) -> 85.142857 | D9: =IF(C9="",IF(D8="",$B$3,D8),D8+C9) -> 1121.8095
A10: =IF('Trade Log'!O7="","",4) | B10: =IF('Trade Log'!O7="","",'Trade Log'!O7) | C10: =IF(B10="","",$B$4*B10) | D10: =IF(C10="",IF(D9="",$B$3,D9),D9+C10) -> 1121.8095
A11: =IF('Trade Log'!O8="","",5) | B11: =IF('Trade Log'!O8="","",'Trade Log'!O8) | C11: =IF(B11="","",$B$4*B11) | D11: =IF(C11="",IF(D10="",$B$3,D10),D10+C11) -> 1121.8095
A12: =IF('Trade Log'!O9="","",6) | B12: =IF('Trade Log'!O9="","",'Trade Log'!O9) | C12: =IF(B12="","",$B$4*B12) | D12: =IF(C12="",IF(D11="",$B$3,D11),D11+C12) -> 1121.8095
A13: =IF('Trade Log'!O10="","",7) | B13: =IF('Trade Log'!O10="","",'Trade Log'!O10) | C13: =IF(B13="","",$B$4*B13) | D13: =IF(C13="",IF(D12="",$B$3,D12),D12+C13) -> 1121.8095
A14: =IF('Trade Log'!O11="","",8) | B14: =IF('Trade Log'!O11="","",'Trade Log'!O11) | C14: =IF(B14="","",$B$4*B14) | D14: =IF(C14="",IF(D13="",$B$3,D13),D13+C14) -> 1121.8095
A15: =IF('Trade Log'!O12="","",9) | B15: =IF('Trade Log'!O12="","",'Trade Log'!O12) | C15: =IF(B15="","",$B$4*B15) | D15: =IF(C15="",IF(D14="",$B$3,D14),D14+C15) -> 1121.8095
A16: =IF('Trade Log'!O13="","",10) | B16: =IF('Trade Log'!O13="","",'Trade Log'!O13) | C16: =IF(B16="","",$B$4*B16) | D16: =IF(C16="",IF(D15="",$B$3,D15),D15+C16) -> 1121.8095
A17: =IF('Trade Log'!O14="","",11) | B17: =IF('Trade Log'!O14="","",'Trade Log'!O14) | C17: =IF(B17="","",$B$4*B17) | D17: =IF(C17="",IF(D16="",$B$3,D16),D16+C17) -> 1121.8095
A18: =IF('Trade Log'!O15="","",12) | B18: =IF('Trade Log'!O15="","",'Trade Log'!O15) | C18: =IF(B18="","",$B$4*B18) | D18: =IF(C18="",IF(D17="",$B$3,D17),D17+C18) -> 1121.8095
A19: =IF('Trade Log'!O16="","",13) | B19: =IF('Trade Log'!O16="","",'Trade Log'!O16) | C19: =IF(B19="","",$B$4*B19) | D19: =IF(C19="",IF(D18="",$B$3,D18),D18+C19) -> 1121.8095
A20: =IF('Trade Log'!O17="","",14) | B20: =IF('Trade Log'!O17="","",'Trade Log'!O17) | C20: =IF(B20="","",$B$4*B20) | D20: =IF(C20="",IF(D19="",$B$3,D19),D19+C20) -> 1121.8095
A21: =IF('Trade Log'!O18="","",15) | B21: =IF('Trade Log'!O18="","",'Trade Log'!O18) | C21: =IF(B21="","",$B$4*B21) | D21: =IF(C21="",IF(D20="",$B$3,D20),D20+C21) -> 1121.8095
A22: =IF('Trade Log'!O19="","",16) | B22: =IF('Trade Log'!O19="","",'Trade Log'!O19) | C22: =IF(B22="","",$B$4*B22) | D22: =IF(C22="",IF(D21="",$B$3,D21),D21+C22) -> 1121.8095
A23: =IF('Trade Log'!O20="","",17) | B23: =IF('Trade Log'!O20="","",'Trade Log'!O20) | C23: =IF(B23="","",$B$4*B23) | D23: =IF(C23="",IF(D22="",$B$3,D22),D22+C23) -> 1121.8095
A24: =IF('Trade Log'!O21="","",18) | B24: =IF('Trade Log'!O21="","",'Trade Log'!O21) | C24: =IF(B24="","",$B$4*B24) | D24: =IF(C24="",IF(D23="",$B$3,D23),D23+C24) -> 1121.8095
A25: =IF('Trade Log'!O22="","",19) | B25: =IF('Trade Log'!O22="","",'Trade Log'!O22) | C25: =IF(B25="","",$B$4*B25) | D25: =IF(C25="",IF(D24="",$B$3,D24),D24+C25) -> 1121.8095
A26: =IF('Trade Log'!O23="","",20) | B26: =IF('Trade Log'!O23="","",'Trade Log'!O23) | C26: =IF(B26="","",$B$4*B26) | D26: =IF(C26="",IF(D25="",$B$3,D25),D25+C26) -> 1121.8095
A27: =IF('Trade Log'!O24="","",21) | B27: =IF('Trade Log'!O24="","",'Trade Log'!O24) | C27: =IF(B27="","",$B$4*B27) | D27: =IF(C27="",IF(D26="",$B$3,D26),D26+C27) -> 1121.8095
A28: =IF('Trade Log'!O25="","",22) | B28: =IF('Trade Log'!O25="","",'Trade Log'!O25) | C28: =IF(B28="","",$B$4*B28) | D28: =IF(C28="",IF(D27="",$B$3,D27),D27+C28) -> 1121.8095
A29: =IF('Trade Log'!O26="","",23) | B29: =IF('Trade Log'!O26="","",'Trade Log'!O26) | C29: =IF(B29="","",$B$4*B29) | D29: =IF(C29="",IF(D28="",$B$3,D28),D28+C29) -> 1121.8095
A30: =IF('Trade Log'!O27="","",24) | B30: =IF('Trade Log'!O27="","",'Trade Log'!O27) | C30: =IF(B30="","",$B$4*B30) | D30: =IF(C30="",IF(D29="",$B$3,D29),D29+C30) -> 1121.8095
A31: =IF('Trade Log'!O28="","",25) | B31: =IF('Trade Log'!O28="","",'Trade Log'!O28) | C31: =IF(B31="","",$B$4*B31) | D31: =IF(C31="",IF(D30="",$B$3,D30),D30+C31) -> 1121.8095
A32: =IF('Trade Log'!O29="","",26) | B32: =IF('Trade Log'!O29="","",'Trade Log'!O29) | C32: =IF(B32="","",$B$4*B32) | D32: =IF(C32="",IF(D31="",$B$3,D31),D31+C32) -> 1121.8095
A33: =IF('Trade Log'!O30="","",27) | B33: =IF('Trade Log'!O30="","",'Trade Log'!O30) | C33: =IF(B33="","",$B$4*B33) | D33: =IF(C33="",IF(D32="",$B$3,D32),D32+C33) -> 1121.8095
A34: =IF('Trade Log'!O31="","",28) | B34: =IF('Trade Log'!O31="","",'Trade Log'!O31) | C34: =IF(B34="","",$B$4*B34) | D34: =IF(C34="",IF(D33="",$B$3,D33),D33+C34) -> 1121.8095
A35: =IF('Trade Log'!O32="","",29) | B35: =IF('Trade Log'!O32="","",'Trade Log'!O32) | C35: =IF(B35="","",$B$4*B35) | D35: =IF(C35="",IF(D34="",$B$3,D34),D34+C35) -> 1121.8095
A36: =IF('Trade Log'!O33="","",30) | B36: =IF('Trade Log'!O33="","",'Trade Log'!O33) | C36: =IF(B36="","",$B$4*B36) | D36: =IF(C36="",IF(D35="",$B$3,D35),D35+C36) -> 1121.8095
A37: =IF('Trade Log'!O34="","",31) | B37: =IF('Trade Log'!O34="","",'Trade Log'!O34) | C37: =IF(B37="","",$B$4*B37) | D37: =IF(C37="",IF(D36="",$B$3,D36),D36+C37) -> 1121.8095
A38: =IF('Trade Log'!O35="","",32) | B38: =IF('Trade Log'!O35="","",'Trade Log'!O35) | C38: =IF(B38="","",$B$4*B38) | D38: =IF(C38="",IF(D37="",$B$3,D37),D37+C38) -> 1121.8095
A39: =IF('Trade Log'!O36="","",33) | B39: =IF('Trade Log'!O36="","",'Trade Log'!O36) | C39: =IF(B39="","",$B$4*B39) | D39: =IF(C39="",IF(D38="",$B$3,D38),D38+C39) -> 1121.8095
A40: =IF('Trade Log'!O37="","",34) | B40: =IF('Trade Log'!O37="","",'Trade Log'!O37) | C40: =IF(B40="","",$B$4*B40) | D40: =IF(C40="",IF(D39="",$B$3,D39),D39+C40) -> 1121.8095
A41: =IF('Trade Log'!O38="","",35) | B41: =IF('Trade Log'!O38="","",'Trade Log'!O38) | C41: =IF(B41="","",$B$4*B41) | D41: =IF(C41="",IF(D40="",$B$3,D40),D40+C41) -> 1121.8095
A42: =IF('Trade Log'!O39="","",36) | B42: =IF('Trade Log'!O39="","",'Trade Log'!O39) | C42: =IF(B42="","",$B$4*B42) | D42: =IF(C42="",IF(D41="",$B$3,D41),D41+C42) -> 1121.8095
...
